Workbook

Sheet Resumen
A1: RESUMEN DE COSTEO POR PAQUETE DE TRABAJO - SISTEMA WEB TORCLY (ESCENARIO DE MERCADO)
A3: Código | B3: Paquete de trabajo | C3: Horas RR.HH. | D3: Costo RR.HH. (S/) | E3: Equipos / Infraestructura (S/) | F3: Consumibles / Servicios (S/) | G3: Costo del paquete (S/) | H3: % del total | J3: Categoría | K3: Monto (S/)
A4: 1.1 | B4: Formalización del Proyecto | C4: =SUM('1.1 Formalización del Proyecto'!E6:E10,'1.1 Formalización del Proyecto'!E13:E17,'1.1 Formalización del Proyecto'!E20:E24) -> 8 | D4: ='1.1 Formalización del Proyecto'!D27 -> 224.2 | E4: ='1.1 Formalización del Proyecto'!H27 -> 0 | F4: ='1.1 Formalización del Proyecto'!M27 -> 0 | G4: ='1.1 Formalización del Proyecto'!P28 -> 224.2 | H4: =G4/$G$32 -> 0.0098114023 | J4: Recursos humanos | K4: =D42 -> 17158.3
A5: 1.2 | B5: Planificación del Proyecto | C5: =SUM('1.2 Planificación del Proyecto'!E6:E10,'1.2 Planificación del Proyecto'!E13:E17,'1.2 Planificación del Proyecto'!E20:E24) -> 36 | D5: ='1.2 Planificación del Proyecto'!D27 -> 1008.9 | E5: ='1.2 Planificación del Proyecto'!H27 -> 0 | F5: ='1.2 Planificación del Proyecto'!M27 -> 200 | G5: ='1.2 Planificación del Proyecto'!P28 -> 1208.9 | H5: =G5/$G$32 -> 0.052903676 | J5: Infraestructura tecnológica | K5: 1200
A6: 2.1 | B6: Especificación Funcional | C6: =SUM('2.1 Especificación Funcional'!E6:E10,'2.1 Especificación Funcional'!E13:E17,'2.1 Especificación Funcional'!E20:E24) -> 12 | D6: ='2.1 Especificación Funcional'!D27 -> 297.6 | E6: ='2.1 Especificación Funcional'!H27 -> 0 | F6: ='2.1 Especificación Funcional'!M27 -> 0 | G6: ='2.1 Especificación Funcional'!P28 -> 297.6 | H6: =G6/$G$32 -> 0.013023521 | J6: Hardware y equipamiento | K6: 1000
A7: 2.2 | B7: Modelamiento Funcional | C7: =SUM('2.2 Modelamiento Funcional'!E6:E10,'2.2 Modelamiento Funcional'!E13:E17,'2.2 Modelamiento Funcional'!E20:E24) -> 24 | D7: ='2.2 Modelamiento Funcional'!D27 -> 608.1 | E7: ='2.2 Modelamiento Funcional'!H27 -> 0 | F7: ='2.2 Modelamiento Funcional'!M27 -> 0 | G7: ='2.2 Modelamiento Funcional'!P28 -> 608.1 | H7: =G7/$G$32 -> 0.026611569 | J7: Software y herramientas | K7: 800
A8: 2.3 | B8: Diseño de Arquitectura | C8: =SUM('2.3 Diseño de Arquitectura'!E6:E10,'2.3 Diseño de Arquitectura'!E13:E17,'2.3 Diseño de Arquitectura'!E20:E24) -> 32 | D8: ='2.3 Diseño de Arquitectura'!D27 -> 741.2 | E8: ='2.3 Diseño de Arquitectura'!H27 -> 0 | F8: ='2.3 Diseño de Arquitectura'!M27 -> 0 | G8: ='2.3 Diseño de Arquitectura'!P28 -> 741.2 | H8: =G8/$G$32 -> 0.032436268 | J8: Pruebas e implementación | K8: 1000
A9: 2.4 | B9: Diseño de Datos | C9: =SUM('2.4 Diseño de Datos'!E6:E10,'2.4 Diseño de Datos'!E13:E17,'2.4 Diseño de Datos'!E20:E24) -> 28 | D9: ='2.4 Diseño de Datos'!D27 -> 686.9 | E9: ='2.4 Diseño de Datos'!H27 -> 0 | F9: ='2.4 Diseño de Datos'!M27 -> 0 | G9: ='2.4 Diseño de Datos'!P28 -> 686.9 | H9: =G9/$G$32 -> 0.030060001 | J9: Contingencia | K9: =G31 -> 1692.664
A10: 2.5 | B10: Diseño UI/UX | C10: =SUM('2.5 Diseño UI-UX'!E6:E10,'2.5 Diseño UI-UX'!E13:E17,'2.5 Diseño UI-UX'!E20:E24) -> 20 | D10: ='2.5 Diseño UI-UX'!D27 -> 449.8 | E10: ='2.5 Diseño UI-UX'!H27 -> 0 | F10: ='2.5 Diseño UI-UX'!M27 -> 200 | G10: ='2.5 Diseño UI-UX'!P28 -> 649.8 | H10: =G10/$G$32 -> 0.028436437
A11: 3.1 | B11: Control de Acceso a Torcly | C11: =SUM('3.1 Control de Acceso a Torcly'!E6:E10,'3.1 Control de Acceso a Torcly'!E13:E17,'3.1 Control de Acceso a Torcly'!E20:E24) -> 52 | D11: ='3.1 Control de Acceso a Torcly'!D27 -> 1186.7 | E11: ='3.1 Control de Acceso a Torcly'!H27 -> 0 | F11: ='3.1 Control de Acceso a Torcly'!M27 -> 0 | G11: ='3.1 Control de Acceso a Torcly'!P28 -> 1186.7 | H11: =G11/$G$32 -> 0.051932164
A12: 4.1 | B12: Gestión de Clientes | C12: =SUM('4.1 Gestión de Clientes'!E6:E10,'4.1 Gestión de Clientes'!E13:E17,'4.1 Gestión de Clientes'!E20:E24) -> 24 | D12: ='4.1 Gestión de Clientes'!D27 -> 555.15 | E12: ='4.1 Gestión de Clientes'!H27 -> 0 | F12: ='4.1 Gestión de Clientes'!M27 -> 0 | G12: ='4.1 Gestión de Clientes'!P28 -> 555.15 | H12: =G12/$G$32 -> 0.02429438
A13: 4.2 | B13: Gestión de Vehículos | C13: =SUM('4.2 Gestión de Vehículos'!E6:E10,'4.2 Gestión de Vehículos'!E13:E17,'4.2 Gestión de Vehículos'!E20:E24) -> 24 | D13: ='4.2 Gestión de Vehículos'!D27 -> 543.45 | E13: ='4.2 Gestión de Vehículos'!H27 -> 0 | F13: ='4.2 Gestión de Vehículos'!M27 -> 0 | G13: ='4.2 Gestión de Vehículos'!P28 -> 543.45 | H13: =G13/$G$32 -> 0.023782366
A14: 5.1 | B14: Catálogo de Productos | C14: =SUM('5.1 Catálogo de Productos'!E6:E10,'5.1 Catálogo de Productos'!E13:E17,'5.1 Catálogo de Productos'!E20:E24) -> 24 | D14: ='5.1 Catálogo de Productos'!D27 -> 591.1 | E14: ='5.1 Catálogo de Productos'!H27 -> 0 | F14: ='5.1 Catálogo de Productos'!M27 -> 0 | G14: ='5.1 Catálogo de Productos'!P28 -> 591.1 | H14: =G14/$G$32 -> 0.025867618
A15: 5.2 | B15: Control de Inventario | C15: =SUM('5.2 Control de Inventario'!E6:E10,'5.2 Control de Inventario'!E13:E17,'5.2 Control de Inventario'!E20:E24) -> 40 | D15: ='5.2 Control de Inventario'!D27 -> 990.6 | E15: ='5.2 Control de Inventario'!H27 -> 1000 | F15: ='5.2 Control de Inventario'!M27 -> 0 | G15: ='5.2 Control de Inventario'!P28 -> 1990.6 | H15: =G15/$G$32 -> 0.087112299
A16: 6.1 | B16: Catálogo de Servicios | C16: =SUM('6.1 Catálogo de Servicios'!E6:E10,'6.1 Catálogo de Servicios'!E13:E17,'6.1 Catálogo de Servicios'!E20:E24) -> 24 | D16: ='6.1 Catálogo de Servicios'!D27 -> 537.3 | E16: ='6.1 Catálogo de Servicios'!H27 -> 0 | F16: ='6.1 Catálogo de Servicios'!M27 -> 0 | G16: ='6.1 Catálogo de Servicios'!P28 -> 537.3 | H16: =G16/$G$32 -> 0.023513231
A17: 7.1 | B17: Agenda del Taller | C17: =SUM('7.1 Agenda del Taller'!E6:E10,'7.1 Agenda del Taller'!E13:E17,'7.1 Agenda del Taller'!E20:E24) -> 36 | D17: ='7.1 Agenda del Taller'!D27 -> 858.6 | E17: ='7.1 Agenda del Taller'!H27 -> 0 | F17: ='7.1 Agenda del Taller'!M27 -> 0 | G17: ='7.1 Agenda del Taller'!P28 -> 858.6 | H17: =G17/$G$32 -> 0.037573907
A18: 8.1 | B18: Orden de Trabajo | C18: =SUM('8.1 Orden de Trabajo'!E6:E10,'8.1 Orden de Trabajo'!E13:E17,'8.1 Orden de Trabajo'!E20:E24) -> 56 | D18: ='8.1 Orden de Trabajo'!D27 -> 1344.4 | E18: ='8.1 Orden de Trabajo'!H27 -> 0 | F18: ='8.1 Orden de Trabajo'!M27 -> 0 | G18: ='8.1 Orden de Trabajo'!P28 -> 1344.4 | H18: =G18/$G$32 -> 0.058833404
A19: 8.2 | B19: Seguimiento del Taller | C19: =SUM('8.2 Seguimiento del Taller'!E6:E10,'8.2 Seguimiento del Taller'!E13:E17,'8.2 Seguimiento del Taller'!E20:E24) -> 16 | D19: ='8.2 Seguimiento del Taller'!D27 -> 368.45 | E19: ='8.2 Seguimiento del Taller'!H27 -> 0 | F19: ='8.2 Seguimiento del Taller'!M27 -> 0 | G19: ='8.2 Seguimiento del Taller'!P28 -> 368.45 | H19: =G19/$G$32 -> 0.016124046
A20: 9.1 | B20: Gestión de Ventas | C20: =SUM('9.1 Gestión de Ventas'!E6:E10,'9.1 Gestión de Ventas'!E13:E17,'9.1 Gestión de Ventas'!E20:E24) -> 16 | D20: ='9.1 Gestión de Ventas'!D27 -> 356.15 | E20: ='9.1 Gestión de Ventas'!H27 -> 0 | F20: ='9.1 Gestión de Ventas'!M27 -> 0 | G20: ='9.1 Gestión de Ventas'!P28 -> 356.15 | H20: =G20/$G$32 -> 0.015585776
A21: 9.2 | B21: Gestión de Pagos | C21: =SUM('9.2 Gestión de Pagos'!E6:E10,'9.2 Gestión de Pagos'!E13:E17,'9.2 Gestión de Pagos'!E20:E24) -> 28 | D21: ='9.2 Gestión de Pagos'!D27 -> 686.9 | E21: ='9.2 Gestión de Pagos'!H27 -> 0 | F21: ='9.2 Gestión de Pagos'!M27 -> 0 | G21: ='9.2 Gestión de Pagos'!P28 -> 686.9 | H21: =G21/$G$32 -> 0.030060001
A22: 10.1 | B22: Consulta Centralizada | C22: =SUM('10.1 Consulta Centralizada'!E6:E10,'10.1 Consulta Centralizada'!E13:E17,'10.1 Consulta Centralizada'!E20:E24) -> 20 | D22: ='10.1 Consulta Centralizada'!D27 -> 502.45 | E22: ='10.1 Consulta Centralizada'!H27 -> 0 | F22: ='10.1 Consulta Centralizada'!M27 -> 0 | G22: ='10.1 Consulta Centralizada'!P28 -> 502.45 | H22: =G22/$G$32 -> 0.021988131
A23: 11.1 | B23: Panel Analítico de Torcly | C23: =SUM('11.1 Panel Analítico de Torcly'!E6:E10,'11.1 Panel Analítico de Torcly'!E13:E17,'11.1 Panel Analítico de Torcly'!E20:E24) -> 36 | D23: ='11.1 Panel Analítico de Torcly'!D27 -> 870.075 | E23: ='11.1 Panel Analítico de Torcly'!H27 -> 0 | F23: ='11.1 Panel Analítico de Torcly'!M27 -> 200 | G23: ='11.1 Panel Analítico de Torcly'!P28 -> 1070.075 | H23: =G23/$G$32 -> 0.04682844
A24: 12.1 | B24: Motor de Apoyo a Reposición | C24: =SUM('12.1 Motor de Apoyo a Reposició'!E6:E10,'12.1 Motor de Apoyo a Reposició'!E13:E17,'12.1 Motor de Apoyo a Reposició'!E20:E24) -> 44 | D24: ='12.1 Motor de Apoyo a Reposició'!D27 -> 1044.825 | E24: ='12.1 Motor de Apoyo a Reposició'!H27 -> 0 | F24: ='12.1 Motor de Apoyo a Reposició'!M27 -> 200 | G24: ='12.1 Motor de Apoyo a Reposició'!P28 -> 1244.825 | H24: =G24/$G$32 -> 0.05447582
A25: 13.1 | B25: Aseguramiento de Calidad | C25: =SUM('13.1 Aseguramiento de Calidad'!E6:E10,'13.1 Aseguramiento de Calidad'!E13:E17,'13.1 Aseguramiento de Calidad'!E20:E24) -> 48 | D25: ='13.1 Aseguramiento de Calidad'!D27 -> 1142.375 | E25: ='13.1 Aseguramiento de Calidad'!H27 -> 0 | F25: ='13.1 Aseguramiento de Calidad'!M27 -> 600 | G25: ='13.1 Aseguramiento de Calidad'!P28 -> 1742.375 | H25: =G25/$G$32 -> 0.076249518
A26: 13.2 | B26: Implementación | C26: =SUM('13.2 Implementación'!E6:E10,'13.2 Implementación'!E13:E17,'13.2 Implementación'!E20:E24) -> 16 | D26: ='13.2 Implementación'!D27 -> 364.45 | E26: ='13.2 Implementación'!H27 -> 1200 | F26: ='13.2 Implementación'!M27 -> 400 | G26: ='13.2 Implementación'!P28 -> 1964.45 | H26: =G26/$G$32 -> 0.085967927
A27: 13.3 | B27: Transferencia de Conocimiento | C27: =SUM('13.3 Transferencia de Conocimie'!E6:E10,'13.3 Transferencia de Conocimie'!E13:E17,'13.3 Transferencia de Conocimie'!E20:E24) -> 32 | D27: ='13.3 Transferencia de Conocimie'!D27 -> 750.225 | E27: ='13.3 Transferencia de Conocimie'!H27 -> 0 | F27: ='13.3 Transferencia de Conocimie'!M27 -> 0 | G27: ='13.3 Transferencia de Conocimie'!P28 -> 750.225 | H27: =G27/$G$32 -> 0.032831219
A28: 13.4 | B28: Cierre del Proyecto | C28: =SUM('13.4 Cierre del Proyecto'!E6:E10,'13.4 Cierre del Proyecto'!E13:E17,'13.4 Cierre del Proyecto'!E20:E24) -> 16 | D28: ='13.4 Cierre del Proyecto'!D27 -> 448.4 | E28: ='13.4 Cierre del Proyecto'!H27 -> 0 | F28: ='13.4 Cierre del Proyecto'!M27 -> 0 | G28: ='13.4 Cierre del Proyecto'!P28 -> 448.4 | H28: =G28/$G$32 -> 0.019622805
A30: SUBTOTAL PAQUETES DE TRABAJO | G30: =SUM(G4:G28) -> 21158.3
A31: RESERVA DE CONTINGENCIA | G31: =G30*Supuestos!$B$15 -> 1692.664
A32: TOTAL PRESUPUESTO DEL PROYECTO | G32: =G30+G31 -> 22850.964 | H32: 1
A35: VALORIZACIÓN DE RECURSOS HUMANOS | F35: COMPARACIÓN PRESUPUESTARIA
A36: Recurso | B36: Horas | C36: Tarifa/hora (S/) | D36: Costo total (S/) | F36: Concepto | G36: Monto / Valor | H36: Comentario
A37: José Manuel Sebastián Mercado Rojas | B37: =SUMIF('1.1 Formalización del Proyecto'!$D$6:$D$24,A37,'1.1 Formalización del Proyecto'!$E$6:$E$24)+SUMIF('1.2 Planificación del Proyecto'!$D$6:$D$24,A37,'1.2 Planificación del Proyecto'!$E$6:$E$24)+SUMIF('2.1 Especificación Funcional'!$D$6:$D$24,A37,'2.1 Especificación Funcional'!$E$6:$E$24)+SUMIF('2.2 Modelamiento Funcional'!$D$6:$D$24,A37,'2.2 Modelamiento Funcional'!$E$6:$E$24)+SUMIF('2.3 Diseño de Arquitectura'!$D$6:$D$24,A37,'2.3 Diseño de Arquitectura'!$E$6:$E$24)+SUMIF('2.4 Diseño de Datos'!$D$6:$D$24,A37,'2.4 Diseño de Datos'!$E$6:$E$24)+SUMIF('2.5 Diseño UI-UX'!$D$6:$D$24,A37,'2.5 Diseño UI-UX'!$E$6:$E$24)+SUMIF('3.1 Control de Acceso a Torcly'!$D$6:$D$24,A37,'3.1 Control de Acceso a Torcly'!$E$6:$E$24)+SUMIF('4.1 Gestión de Clientes'!$D$6:$D$24,A37,'4.1 Gestión de Clientes'!$E$6:$E$24)+SUMIF('4.2 Gestión de Vehículos'!$D$6:$D$24,A37,'4.2 Gestión de Vehículos'!$E$6:$E$24)+SUMIF('5.1 Catálogo de Productos'!$D$6:$D$24,A37,'5.1 Catálogo de Productos'!$E$6:$E$24)+SUMIF('5.2 Control de Inventario'!$D$6:$D$24,A37,'5.2 Control de Inventario'!$E$6:$E$24)+SUMIF('6.1 Catálogo de Servicios'!$D$6:$D$24,A37,'6.1 Catálogo de Servicios'!$E$6:$E$24)+SUMIF('7.1 Agenda del Taller'!$D$6:$D$24,A37,'7.1 Agenda del Taller'!$E$6:$E$24)+SUMIF('8.1 Orden de Trabajo'!$D$6:$D$24,A37,'8.1 Orden de Trabajo'!$E$6:$E$24)+SUMIF('8.2 Seguimiento del Taller'!$D$6:$D$24,A37,'8.2 Seguimiento del Taller'!$E$6:$E$24)+SUMIF('9.1 Gestión de Ventas'!$D$6:$D$24,A37,'9.1 Gestión de Ventas'!$E$6:$E$24)+SUMIF('9.2 Gestión de Pagos'!$D$6:$D$24,A37,'9.2 Gestión de Pagos'!$E$6:$E$24)+SUMIF('10.1 Consulta Centralizada'!$D$6:$D$24,A37,'10.1 Consulta Centralizada'!$E$6:$E$24)+SUMIF('11.1 Panel Analítico de Torcly'!$D$6:$D$24,A37,'11.1 Panel Analítico de Torcly'!$E$6:$E$24)+SUMIF('12.1 Motor de Apoyo a Reposició'!$D$6:$D$24,A37,'12.1 Motor de Apoyo a Reposició'!$E$6:$E$24)+SUMIF('13.1 Aseguramiento de Calidad'!$D$6:$D$24,A37,'13.1 Aseguramiento de Calidad'!$E$6:$E$24)+SUMIF('13.2 Implementación'!$D$6:$D$24,A37,'13.2 Implementación'!$E$6:$E$24)+SUMIF('13.3 Transferencia de Conocimie'!$D$6:$D$24,A37,'13.3 Transferencia de Conocimie'!$E$6:$E$24)+SUMIF('13.4 Cierre del Proyecto'!$D$6:$D$24,A37,'13.4 Cierre del Proyecto'!$E$6:$E$24) -> 142 | C37: =Supuestos!$E$4 -> 28.025 | D37: =B37*C37 -> 3979.55 | F37: Presupuesto referencial anterior | G37: 10000 | H37: Base previa del Business Case
A38: Arian Armando Bautista Quezada | B38: =SUMIF('1.1 Formalización del Proyecto'!$D$6:$D$24,A38,'1.1 Formalización del Proyecto'!$E$6:$E$24)+SUMIF('1.2 Planificación del Proyecto'!$D$6:$D$24,A38,'1.2 Planificación del Proyecto'!$E$6:$E$24)+SUMIF('2.1 Especificación Funcional'!$D$6:$D$24,A38,'2.1 Especificación Funcional'!$E$6:$E$24)+SUMIF('2.2 Modelamiento Funcional'!$D$6:$D$24,A38,'2.2 Modelamiento Funcional'!$E$6:$E$24)+SUMIF('2.3 Diseño de Arquitectura'!$D$6:$D$24,A38,'2.3 Diseño de Arquitectura'!$E$6:$E$24)+SUMIF('2.4 Diseño de Datos'!$D$6:$D$24,A38,'2.4 Diseño de Datos'!$E$6:$E$24)+SUMIF('2.5 Diseño UI-UX'!$D$6:$D$24,A38,'2.5 Diseño UI-UX'!$E$6:$E$24)+SUMIF('3.1 Control de Acceso a Torcly'!$D$6:$D$24,A38,'3.1 Control de Acceso a Torcly'!$E$6:$E$24)+SUMIF('4.1 Gestión de Clientes'!$D$6:$D$24,A38,'4.1 Gestión de Clientes'!$E$6:$E$24)+SUMIF('4.2 Gestión de Vehículos'!$D$6:$D$24,A38,'4.2 Gestión de Vehículos'!$E$6:$E$24)+SUMIF('5.1 Catálogo de Productos'!$D$6:$D$24,A38,'5.1 Catálogo de Productos'!$E$6:$E$24)+SUMIF('5.2 Control de Inventario'!$D$6:$D$24,A38,'5.2 Control de Inventario'!$E$6:$E$24)+SUMIF('6.1 Catálogo de Servicios'!$D$6:$D$24,A38,'6.1 Catálogo de Servicios'!$E$6:$E$24)+SUMIF('7.1 Agenda del Taller'!$D$6:$D$24,A38,'7.1 Agenda del Taller'!$E$6:$E$24)+SUMIF('8.1 Orden de Trabajo'!$D$6:$D$24,A38,'8.1 Orden de Trabajo'!$E$6:$E$24)+SUMIF('8.2 Seguimiento del Taller'!$D$6:$D$24,A38,'8.2 Seguimiento del Taller'!$E$6:$E$24)+SUMIF('9.1 Gestión de Ventas'!$D$6:$D$24,A38,'9.1 Gestión de Ventas'!$E$6:$E$24)+SUMIF('9.2 Gestión de Pagos'!$D$6:$D$24,A38,'9.2 Gestión de Pagos'!$E$6:$E$24)+SUMIF('10.1 Consulta Centralizada'!$D$6:$D$24,A38,'10.1 Consulta Centralizada'!$E$6:$E$24)+SUMIF('11.1 Panel Analítico de Torcly'!$D$6:$D$24,A38,'11.1 Panel Analítico de Torcly'!$E$6:$E$24)+SUMIF('12.1 Motor de Apoyo a Reposició'!$D$6:$D$24,A38,'12.1 Motor de Apoyo a Reposició'!$E$6:$E$24)+SUMIF('13.1 Aseguramiento de Calidad'!$D$6:$D$24,A38,'13.1 Aseguramiento de Calidad'!$E$6:$E$24)+SUMIF('13.2 Implementación'!$D$6:$D$24,A38,'13.2 Implementación'!$E$6:$E$24)+SUMIF('13.3 Transferencia de Conocimie'!$D$6:$D$24,A38,'13.3 Transferencia de Conocimie'!$E$6:$E$24)+SUMIF('13.4 Cierre del Proyecto'!$D$6:$D$24,A38,'13.4 Cierre del Proyecto'!$E$6:$E$24) -> 142 | C38: =Supuestos!$E$5 -> 24.8 | D38: =B38*C38 -> 3521.6 | F38: Nuevo estimado de mercado | G38: =G32 -> 22850.964 | H38: Calculado con tarifas salariales de mercado y 8% de contingencia
A39: Brenda Gabriela Ormeño Bocanegra | B39: =SUMIF('1.1 Formalización del Proyecto'!$D$6:$D$24,A39,'1.1 Formalización del Proyecto'!$E$6:$E$24)+SUMIF('1.2 Planificación del Proyecto'!$D$6:$D$24,A39,'1.2 Planificación del Proyecto'!$E$6:$E$24)+SUMIF('2.1 Especificación Funcional'!$D$6:$D$24,A39,'2.1 Especificación Funcional'!$E$6:$E$24)+SUMIF('2.2 Modelamiento Funcional'!$D$6:$D$24,A39,'2.2 Modelamiento Funcional'!$E$6:$E$24)+SUMIF('2.3 Diseño de Arquitectura'!$D$6:$D$24,A39,'2.3 Diseño de Arquitectura'!$E$6:$E$24)+SUMIF('2.4 Diseño de Datos'!$D$6:$D$24,A39,'2.4 Diseño de Datos'!$E$6:$E$24)+SUMIF('2.5 Diseño UI-UX'!$D$6:$D$24,A39,'2.5 Diseño UI-UX'!$E$6:$E$24)+SUMIF('3.1 Control de Acceso a Torcly'!$D$6:$D$24,A39,'3.1 Control de Acceso a Torcly'!$E$6:$E$24)+SUMIF('4.1 Gestión de Clientes'!$D$6:$D$24,A39,'4.1 Gestión de Clientes'!$E$6:$E$24)+SUMIF('4.2 Gestión de Vehículos'!$D$6:$D$24,A39,'4.2 Gestión de Vehículos'!$E$6:$E$24)+SUMIF('5.1 Catálogo de Productos'!$D$6:$D$24,A39,'5.1 Catálogo de Productos'!$E$6:$E$24)+SUMIF('5.2 Control de Inventario'!$D$6:$D$24,A39,'5.2 Control de Inventario'!$E$6:$E$24)+SUMIF('6.1 Catálogo de Servicios'!$D$6:$D$24,A39,'6.1 Catálogo de Servicios'!$E$6:$E$24)+SUMIF('7.1 Agenda del Taller'!$D$6:$D$24,A39,'7.1 Agenda del Taller'!$E$6:$E$24)+SUMIF('8.1 Orden de Trabajo'!$D$6:$D$24,A39,'8.1 Orden de Trabajo'!$E$6:$E$24)+SUMIF('8.2 Seguimiento del Taller'!$D$6:$D$24,A39,'8.2 Seguimiento del Taller'!$E$6:$E$24)+SUMIF('9.1 Gestión de Ventas'!$D$6:$D$24,A39,'9.1 Gestión de Ventas'!$E$6:$E$24)+SUMIF('9.2 Gestión de Pagos'!$D$6:$D$24,A39,'9.2 Gestión de Pagos'!$E$6:$E$24)+SUMIF('10.1 Consulta Centralizada'!$D$6:$D$24,A39,'10.1 Consulta Centralizada'!$E$6:$E$24)+SUMIF('11.1 Panel Analítico de Torcly'!$D$6:$D$24,A39,'11.1 Panel Analítico de Torcly'!$E$6:$E$24)+SUMIF('12.1 Motor de Apoyo a Reposició'!$D$6:$D$24,A39,'12.1 Motor de Apoyo a Reposició'!$E$6:$E$24)+SUMIF('13.1 Aseguramiento de Calidad'!$D$6:$D$24,A39,'13.1 Aseguramiento de Calidad'!$E$6:$E$24)+SUMIF('13.2 Implementación'!$D$6:$D$24,A39,'13.2 Implementación'!$E$6:$E$24)+SUMIF('13.3 Transferencia de Conocimie'!$D$6:$D$24,A39,'13.3 Transferencia de Conocimie'!$E$6:$E$24)+SUMIF('13.4 Cierre del Proyecto'!$D$6:$D$24,A39,'13.4 Cierre del Proyecto'!$E$6:$E$24) -> 143 | C39: =Supuestos!$E$6 -> 21.875 | D39: =B39*C39 -> 3128.125 | F39: Variación absoluta | G39: =G38-G37 -> 12850.964 | H39: Diferencia frente al presupuesto anterior
A40: Piero Ramírez Alva | B40: =SUMIF('1.1 Formalización del Proyecto'!$D$6:$D$24,A40,'1.1 Formalización del Proyecto'!$E$6:$E$24)+SUMIF('1.2 Planificación del Proyecto'!$D$6:$D$24,A40,'1.2 Planificación del Proyecto'!$E$6:$E$24)+SUMIF('2.1 Especificación Funcional'!$D$6:$D$24,A40,'2.1 Especificación Funcional'!$E$6:$E$24)+SUMIF('2.2 Modelamiento Funcional'!$D$6:$D$24,A40,'2.2 Modelamiento Funcional'!$E$6:$E$24)+SUMIF('2.3 Diseño de Arquitectura'!$D$6:$D$24,A40,'2.3 Diseño de Arquitectura'!$E$6:$E$24)+SUMIF('2.4 Diseño de Datos'!$D$6:$D$24,A40,'2.4 Diseño de Datos'!$E$6:$E$24)+SUMIF('2.5 Diseño UI-UX'!$D$6:$D$24,A40,'2.5 Diseño UI-UX'!$E$6:$E$24)+SUMIF('3.1 Control de Acceso a Torcly'!$D$6:$D$24,A40,'3.1 Control de Acceso a Torcly'!$E$6:$E$24)+SUMIF('4.1 Gestión de Clientes'!$D$6:$D$24,A40,'4.1 Gestión de Clientes'!$E$6:$E$24)+SUMIF('4.2 Gestión de Vehículos'!$D$6:$D$24,A40,'4.2 Gestión de Vehículos'!$E$6:$E$24)+SUMIF('5.1 Catálogo de Productos'!$D$6:$D$24,A40,'5.1 Catálogo de Productos'!$E$6:$E$24)+SUMIF('5.2 Control de Inventario'!$D$6:$D$24,A40,'5.2 Control de Inventario'!$E$6:$E$24)+SUMIF('6.1 Catálogo de Servicios'!$D$6:$D$24,A40,'6.1 Catálogo de Servicios'!$E$6:$E$24)+SUMIF('7.1 Agenda del Taller'!$D$6:$D$24,A40,'7.1 Agenda del Taller'!$E$6:$E$24)+SUMIF('8.1 Orden de Trabajo'!$D$6:$D$24,A40,'8.1 Orden de Trabajo'!$E$6:$E$24)+SUMIF('8.2 Seguimiento del Taller'!$D$6:$D$24,A40,'8.2 Seguimiento del Taller'!$E$6:$E$24)+SUMIF('9.1 Gestión de Ventas'!$D$6:$D$24,A40,'9.1 Gestión de Ventas'!$E$6:$E$24)+SUMIF('9.2 Gestión de Pagos'!$D$6:$D$24,A40,'9.2 Gestión de Pagos'!$E$6:$E$24)+SUMIF('10.1 Consulta Centralizada'!$D$6:$D$24,A40,'10.1 Consulta Centralizada'!$E$6:$E$24)+SUMIF('11.1 Panel Analítico de Torcly'!$D$6:$D$24,A40,'11.1 Panel Analítico de Torcly'!$E$6:$E$24)+SUMIF('12.1 Motor de Apoyo a Reposició'!$D$6:$D$24,A40,'12.1 Motor de Apoyo a Reposició'!$E$6:$E$24)+SUMIF('13.1 Aseguramiento de Calidad'!$D$6:$D$24,A40,'13.1 Aseguramiento de Calidad'!$E$6:$E$24)+SUMIF('13.2 Implementación'!$D$6:$D$24,A40,'13.2 Implementación'!$E$6:$E$24)+SUMIF('13.3 Transferencia de Conocimie'!$D$6:$D$24,A40,'13.3 Transferencia de Conocimie'!$E$6:$E$24)+SUMIF('13.4 Cierre del Proyecto'!$D$6:$D$24,A40,'13.4 Cierre del Proyecto'!$E$6:$E$24) -> 142 | C40: =Supuestos!$E$7 -> 23.95 | D40: =B40*C40 -> 3400.9 | F40: Variación porcentual | G40: =G39/G37 -> 1.2850964 | H40: Incremento frente al presupuesto anterior
A41: Carmen Katerin Vega Meza | B41: =SUMIF('1.1 Formalización del Proyecto'!$D$6:$D$24,A41,'1.1 Formalización del Proyecto'!$E$6:$E$24)+SUMIF('1.2 Planificación del Proyecto'!$D$6:$D$24,A41,'1.2 Planificación del Proyecto'!$E$6:$E$24)+SUMIF('2.1 Especificación Funcional'!$D$6:$D$24,A41,'2.1 Especificación Funcional'!$E$6:$E$24)+SUMIF('2.2 Modelamiento Funcional'!$D$6:$D$24,A41,'2.2 Modelamiento Funcional'!$E$6:$E$24)+SUMIF('2.3 Diseño de Arquitectura'!$D$6:$D$24,A41,'2.3 Diseño de Arquitectura'!$E$6:$E$24)+SUMIF('2.4 Diseño de Datos'!$D$6:$D$24,A41,'2.4 Diseño de Datos'!$E$6:$E$24)+SUMIF('2.5 Diseño UI-UX'!$D$6:$D$24,A41,'2.5 Diseño UI-UX'!$E$6:$E$24)+SUMIF('3.1 Control de Acceso a Torcly'!$D$6:$D$24,A41,'3.1 Control de Acceso a Torcly'!$E$6:$E$24)+SUMIF('4.1 Gestión de Clientes'!$D$6:$D$24,A41,'4.1 Gestión de Clientes'!$E$6:$E$24)+SUMIF('4.2 Gestión de Vehículos'!$D$6:$D$24,A41,'4.2 Gestión de Vehículos'!$E$6:$E$24)+SUMIF('5.1 Catálogo de Productos'!$D$6:$D$24,A41,'5.1 Catálogo de Productos'!$E$6:$E$24)+SUMIF('5.2 Control de Inventario'!$D$6:$D$24,A41,'5.2 Control de Inventario'!$E$6:$E$24)+SUMIF('6.1 Catálogo de Servicios'!$D$6:$D$24,A41,'6.1 Catálogo de Servicios'!$E$6:$E$24)+SUMIF('7.1 Agenda del Taller'!$D$6:$D$24,A41,'7.1 Agenda del Taller'!$E$6:$E$24)+SUMIF('8.1 Orden de Trabajo'!$D$6:$D$24,A41,'8.1 Orden de Trabajo'!$E$6:$E$24)+SUMIF('8.2 Seguimiento del Taller'!$D$6:$D$24,A41,'8.2 Seguimiento del Taller'!$E$6:$E$24)+SUMIF('9.1 Gestión de Ventas'!$D$6:$D$24,A41,'9.1 Gestión de Ventas'!$E$6:$E$24)+SUMIF('9.2 Gestión de Pagos'!$D$6:$D$24,A41,'9.2 Gestión de Pagos'!$E$6:$E$24)+SUMIF('10.1 Consulta Centralizada'!$D$6:$D$24,A41,'10.1 Consulta Centralizada'!$E$6:$E$24)+SUMIF('11.1 Panel Analítico de Torcly'!$D$6:$D$24,A41,'11.1 Panel Analítico de Torcly'!$E$6:$E$24)+SUMIF('12.1 Motor de Apoyo a Reposició'!$D$6:$D$24,A41,'12.1 Motor de Apoyo a Reposició'!$E$6:$E$24)+SUMIF('13.1 Aseguramiento de Calidad'!$D$6:$D$24,A41,'13.1 Aseguramiento de Calidad'!$E$6:$E$24)+SUMIF('13.2 Implementación'!$D$6:$D$24,A41,'13.2 Implementación'!$E$6:$E$24)+SUMIF('13.3 Transferencia de Conocimie'!$D$6:$D$24,A41,'13.3 Transferencia de Conocimie'!$E$6:$E$24)+SUMIF('13.4 Cierre del Proyecto'!$D$6:$D$24,A41,'13.4 Cierre del Proyecto'!$E$6:$E$24) -> 143 | C41: =Supuestos!$E$8 -> 21.875 | D41: =B41*C41 -> 3128.125
A42: TOTAL RECURSOS HUMANOS | D42: =SUM(D37:D41) -> 17158.3

Sheet Supuestos
A1: SUPUESTOS Y TARIFAS DE COSTEO - TORCLY
A3: Recurso | B3: Rol | C3: Sueldo mensual referencial (S/) | D3: Horas base / mes | E3: Tarifa por hora (S/) | F3: Fuente / criterio
A4: José Manuel Sebastián Mercado Rojas | B4: Líder del Proyecto | C4: 4484 | D4: 160 | E4: =C4/D4 -> 28.025 | F4: Indeed Perú - Jefe de proyectos TI en Lima (actualizado 2026): https://pe.indeed.com/career/jefe-de-proyectos-ti/salaries/Lima--Lima
A5: Arian Armando Bautista Quezada | B5: Analista de Sistemas | C5: 3968 | D5: 160 | E5: =C5/D5 -> 24.8 | F5: Indeed Perú - Analista de sistema en Lima (actualizado 2026): https://pe.indeed.com/career/analista-de-sistema/salaries/Lima--Lima
A6: Brenda Gabriela Ormeño Bocanegra | B6: Programadora Full-Stack | C6: 3500 | D6: 160 | E6: =C6/D6 -> 21.875 | F6: Referencia de mercado: ofertas Full Stack en Perú entre S/ 3,000 y S/ 4,000 mensuales; se usa el punto medio. https://pe.indeed.com/career/desarrollador-de-software/salaries
A7: Piero Ramírez Alva | B7: Administrador de Base de Datos | C7: 3832 | D7: 160 | E7: =C7/D7 -> 23.95 | F7: Indeed Perú - Administrador/a de base de datos (actualizado 2026): https://pe.indeed.com/career/administrador-de-base-de-datos/salaries
A8: Carmen Katerin Vega Meza | B8: Programadora Full-Stack | C8: 3500 | D8: 160 | E8: =C8/D8 -> 21.875 | F8: Referencia de mercado: ofertas Full Stack en Perú entre S/ 3,000 y S/ 4,000 mensuales; se usa el punto medio. https://pe.indeed.com/career/desarrollador-de-software/salaries
A9: Criterio laboral: la tarifa horaria es equivalente al sueldo mensual referencial dividido entre 160 horas/mes. Representa mano de obra directa valorizada; no incorpora beneficios sociales, impuestos ni overhead empresarial.
A10: Categoría no laboral | B10: Monto base (S/) | C10: Asignación | D10: Fuente / criterio
A11: Infraestructura tecnológica | B11: 1200 | C11: 13.2 Implementación | D11: Estimación presupuestaria del proyecto: hosting, dominio y recursos de despliegue.
A12: Hardware y equipamiento | B12: 1000 | C12: 5.2 Control de Inventario | D12: Estimación presupuestaria del proyecto: lector de código de barras y accesorios.
A13: Software y herramientas | B13: 800 | C13: 1.2 / 2.5 / 11.1 / 12.1 | D13: Estimación presupuestaria del proyecto para herramientas de gestión, prototipado, BI e IA.
A14: Pruebas e implementación | B14: 1000 | C14: 13.1 / 13.2 | D14: Estimación presupuestaria del proyecto para pruebas, configuración y despliegue.
A15: Contingencia | B15: 0.08 | C15: Resumen | D15: Reserva calculada como 8% del subtotal del proyecto antes de contingencia.
A17: Conversión de duración | B17: Valor | C17: Aplicación | D17: Observación
A18: 1 día de trabajo | B18: 8 | C18: Cronograma | D18: Se convierte a 8 horas para el costeo
A19: 4 horas | B19: 4 | C19: Cronograma | D19: Se mantiene como 4 horas
A20: Hito | B20: 0 | C20: Cronograma | D20: No agrega horas de ejecución; su trabajo está contenido en actividades previas
A22: Base de estimación: 712 horas del cronograma, distribuidas de forma equilibrada (142–143 h por integrante); tarifas derivadas de referencias salariales de mercado 2026; costos no laborales según supuestos del proyecto; contingencia del 8% calculada sobre el subtotal previo.

Sheet 1.1 Formalización del Proyecto
B2: PAQUETE DE TRABAJO / ENTREGABLE | D2: 1.1 Formalización del Proyecto
B3: ACTIVIDAD | D3: COSTOS
B4: CÓDIGO | C4: DESCRIPCIÓN | D4: RECURSOS HUMANOS | H4: MAQUINARIA / EQUIPOS / INFRAESTRUCTURA | M4: CONSUMIBLES / SERVICIOS
D5: Nombre del Recurso | E5: Número de Horas | F5: Costo x Hora (S/) | G5: Costo Total | H5: Nombre del Recurso | I5: Cantidad | J5: Costo x día (S/) | K5: Nro. de días | L5: Total | M5: Nombre del Recurso | N5: Cantidad | O5: Costo Unitario (S/) | P5: IMPORTE
B6: 1.1.1 | C6: Documentación Fundacional | D6: José Manuel Sebastián Mercado Rojas | E6: 8 | F6: =Supuestos!$E$4 -> 28.025 | G6: =E6*F6 -> 224.2
C11: SUB TOTAL ACTIVIDAD | G11: =SUM(G6:G10) -> 224.2 | L11: =SUM(L6:L10) -> 0 | P11: =SUM(P6:P10) -> 0
C12: TOTAL ACTIVIDAD | P12: =G11+L11+P11 -> 224.2
C18: SUB TOTAL ACTIVIDAD | G18: =SUM(G13:G17) -> 0 | L18: =SUM(L13:L17) -> 0 | P18: =SUM(P13:P17) -> 0
C19: TOTAL ACTIVIDAD | P19: =G18+L18+P18 -> 0
C25: SUB TOTAL ACTIVIDAD | G25: =SUM(G20:G24) -> 0 | L25: =SUM(L20:L24) -> 0 | P25: =SUM(P20:P24) -> 0
C26: TOTAL ACTIVIDAD | P26: =G25+L25+P25 -> 0
B27: SUB TOTAL PAQUETE | D27: =SUM(G11,G18,G25) -> 224.2 | H27: =SUM(L11,L18,L25) -> 0 | M27: =SUM(P11,P18,P25) -> 0
B28: TOTAL PAQUETE | P28: =D27+H27+M27 -> 224.2
B30: Base de costeo: horas del cronograma, responsables R/R-A de la Matriz RACI y tarifas referenciales indicadas en la hoja Supuestos.

Sheet 1.2 Planificación del Proyecto
B2: PAQUETE DE TRABAJO / ENTREGABLE | D2: 1.2 Planificación del Proyecto
B3: ACTIVIDAD | D3: COSTOS
B4: CÓDIGO | C4: DESCRIPCIÓN | D4: RECURSOS HUMANOS | H4: MAQUINARIA / EQUIPOS / INFRAESTRUCTURA | M4: CONSUMIBLES / SERVICIOS
D5: Nombre del Recurso | E5: Número de Horas | F5: Costo x Hora (S/) | G5: Costo Total | H5: Nombre del Recurso | I5: Cantidad | J5: Costo x día (S/) | K5: Nro. de días | L5: Total | M5: Nombre del Recurso | N5: Cantidad | O5: Costo Unitario (S/) | P5: IMPORTE
B6: 1.2.1 | C6: Línea Base de Planificación | D6: José Manuel Sebastián Mercado Rojas | E6: 16 | F6: =Supuestos!$E$4 -> 28.025 | G6: =E6*F6 -> 448.4
C11: SUB TOTAL ACTIVIDAD | G11: =SUM(G6:G10) -> 448.4 | L11: =SUM(L6:L10) -> 0 | P11: =SUM(P6:P10) -> 0
C12: TOTAL ACTIVIDAD | P12: =G11+L11+P11 -> 448.4
B13: 1.2.2 | C13: Gestión Organizacional | D13: José Manuel Sebastián Mercado Rojas | E13: 12 | F13: =Supuestos!$E$4 -> 28.025 | G13: =E13*F13 -> 336.3 | M13: Herramienta de gestión y colaboración | N13: 1 | O13: 200 | P13: =N13*O13 -> 200
C18: SUB TOTAL ACTIVIDAD | G18: =SUM(G13:G17) -> 336.3 | L18: =SUM(L13:L17) -> 0 | P18: =SUM(P13:P17) -> 200
C19: TOTAL ACTIVIDAD | P19: =G18+L18+P18 -> 536.3
B20: 1.2.3 | C20: Gestión de Riesgos | D20: José Manuel Sebastián Mercado Rojas | E20: 8 | F20: =Supuestos!$E$4 -> 28.025 | G20: =E20*F20 -> 224.2
C25: SUB TOTAL ACTIVIDAD | G25: =SUM(G20:G24) -> 224.2 | L25: =SUM(L20:L24) -> 0 | P25: =SUM(P20:P24) -> 0
C26: TOTAL ACTIVIDAD | P26: =G25+L25+P25 -> 224.2
B27: SUB TOTAL PAQUETE | D27: =SUM(G11,G18,G25) -> 1008.9 | H27: =SUM(L11,L18,L25) -> 0 | M27: =SUM(P11,P18,P25) -> 200
B28: TOTAL PAQUETE | P28: =D27+H27+M27 -> 1208.9
B30: Base de costeo: horas del cronograma, responsables R/R-A de la Matriz RACI y tarifas referenciales indicadas en la hoja Supuestos.

Sheet 2.1 Especificación Funcional
B2: PAQUETE DE TRABAJO / ENTREGABLE | D2: 2.1 Especificación Funcional
B3: ACTIVIDAD | D3: COSTOS
B4: CÓDIGO | C4: DESCRIPCIÓN | D4: RECURSOS HUMANOS | H4: MAQUINARIA / EQUIPOS / INFRAESTRUCTURA | M4: CONSUMIBLES / SERVICIOS
D5: Nombre del Recurso | E5: Número de Horas | F5: Costo x Hora (S/) | G5: Costo Total | H5: Nombre del Recurso | I5: Cantidad | J5: Costo x día (S/) | K5: Nro. de días | L5: Total | M5: Nombre del Recurso | N5: Cantidad | O5: Costo Unitario (S/) | P5: IMPORTE
B6: 2.1.1 | C6: Requerimientos del Sistema | D6: Arian Armando Bautista Quezada | E6: 12 | F6: =Supuestos!$E$5 -> 24.8 | G6: =E6*F6 -> 297.6
C11: SUB TOTAL ACTIVIDAD | G11: =SUM(G6:G10) -> 297.6 | L11: =SUM(L6:L10) -> 0 | P11: =SUM(P6:P10) -> 0
C12: TOTAL ACTIVIDAD | P12: =G11+L11+P11 -> 297.6
C18: SUB TOTAL ACTIVIDAD | G18: =SUM(G13:G17) -> 0 | L18: =SUM(L13:L17) -> 0 | P18: =SUM(P13:P17) -> 0
C19: TOTAL ACTIVIDAD | P19: =G18+L18+P18 -> 0
C25: SUB TOTAL ACTIVIDAD | G25: =SUM(G20:G24) -> 0 | L25: =SUM(L20:L24) -> 0 | P25: =SUM(P20:P24) -> 0
C26: TOTAL ACTIVIDAD | P26: =G25+L25+P25 -> 0
B27: SUB TOTAL PAQUETE | D27: =SUM(G11,G18,G25) -> 297.6 | H27: =SUM(L11,L18,L25) -> 0 | M27: =SUM(P11,P18,P25) -> 0
B28: TOTAL PAQUETE | P28: =D27+H27+M27 -> 297.6
B30: Base de costeo: horas del cronograma, responsables R/R-A de la Matriz RACI y tarifas referenciales indicadas en la hoja Supuestos.

Sheet 2.2 Modelamiento Funcional
B2: PAQUETE DE TRABAJO / ENTREGABLE | D2: 2.2 Modelamiento Funcional
B3: ACTIVIDAD | D3: COSTOS
B4: CÓDIGO | C4: DESCRIPCIÓN | D4: RECURSOS HUMANOS | H4: MAQUINARIA / EQUIPOS / INFRAESTRUCTURA | M4: CONSUMIBLES / SERVICIOS
D5: Nombre del Recurso | E5: Número de Horas | F5: Costo x Hora (S/) | G5: Costo Total | H5: Nombre del Recurso | I5: Cantidad | J5: Costo x día (S/) | K5: Nro. de días | L5: Total | M5: Nombre del Recurso | N5: Cantidad | O5: Costo Unitario (S/) | P5: IMPORTE
B6: 2.2.1 | C6: Procesos de Negocio | D6: Arian Armando Bautista Quezada | E6: 20 | F6: =Supuestos!$E$5 -> 24.8 | G6: =E6*F6 -> 496
D7: José Manuel Sebastián Mercado Rojas | E7: 4 | F7: =Supuestos!$E$4 -> 28.025 | G7: =E7*F7 -> 112.1
C11: SUB TOTAL ACTIVIDAD | G11: =SUM(G6:G10) -> 608.1 | L11: =SUM(L6:L10) -> 0 | P11: =SUM(P6:P10) -> 0
C12: TOTAL ACTIVIDAD | P12: =G11+L11+P11 -> 608.1
C18: SUB TOTAL ACTIVIDAD | G18: =SUM(G13:G17) -> 0 | L18: =SUM(L13:L17) -> 0 | P18: =SUM(P13:P17) -> 0
C19: TOTAL ACTIVIDAD | P19: =G18+L18+P18 -> 0
C25: SUB TOTAL ACTIVIDAD | G25: =SUM(G20:G24) -> 0 | L25: =SUM(L20:L24) -> 0 | P25: =SUM(P20:P24) -> 0
C26: TOTAL ACTIVIDAD | P26: =G25+L25+P25 -> 0
B27: SUB TOTAL PAQUETE | D27: =SUM(G11,G18,G25) -> 608.1 | H27: =SUM(L11,L18,L25) -> 0 | M27: =SUM(P11,P18,P25) -> 0
B28: TOTAL PAQUETE | P28: =D27+H27+M27 -> 608.1
B30: Base de costeo: horas del cronograma, responsables R/R-A de la Matriz RACI y tarifas referenciales indicadas en la hoja Supuestos.

Sheet 2.3 Diseño de Arquitectura
B2: PAQUETE DE TRABAJO / ENTREGABLE | D2: 2.3 Diseño de Arquitectura
B3: ACTIVIDAD | D3: COSTOS
B4: CÓDIGO | C4: DESCRIPCIÓN | D4: RECURSOS HUMANOS | H4: MAQUINARIA / EQUIPOS / INFRAESTRUCTURA | M4: CONSUMIBLES / SERVICIOS
D5: Nombre del Recurso | E5: Número de Horas | F5: Costo x Hora (S/) | G5: Costo Total | H5: Nombre del Recurso | I5: Cantidad | J5: Costo x día (S/) | K5: Nro. de días | L5: Total | M5: Nombre del Recurso | N5: Cantidad | O5: Costo Unitario (S/) | P5: IMPORTE
B6: 2.3.1 | C6: Arquitectura de Software | D6: Brenda Gabriela Ormeño Bocanegra | E6: 8 | F6: =Supuestos!$E$6 -> 21.875 | G6: =E6*F6 -> 175
D7: Carmen Katerin Vega Meza | E7: 12 | F7: =Supuestos!$E$8 -> 21.875 | G7: =E7*F7 -> 262.5
D8: Piero Ramírez Alva | E8: 8 | F8: =Supuestos!$E$7 -> 23.95 | G8: =E8*F8 -> 191.6
D9: José Manuel Sebastián Mercado Rojas | E9: 4 | F9: =Supuestos!$E$4 -> 28.025 | G9: =E9*F9 -> 112.1
C11: SUB TOTAL ACTIVIDAD | G11: =SUM(G6:G10) -> 741.2 | L11: =SUM(L6:L10) -> 0 | P11: =SUM(P6:P10) -> 0
C12: TOTAL ACTIVIDAD | P12: =G11+L11+P11 -> 741.2
C18: SUB TOTAL ACTIVIDAD | G18: =SUM(G13:G17) -> 0 | L18: =SUM(L13:L17) -> 0 | P18: =SUM(P13:P17) -> 0
C19: TOTAL ACTIVIDAD | P19: =G18+L18+P18 -> 0
C25: SUB TOTAL ACTIVIDAD | G25: =SUM(G20:G24) -> 0 | L25: =SUM(L20:L24) -> 0 | P25: =SUM(P20:P24) -> 0
C26: TOTAL ACTIVIDAD | P26: =G25+L25+P25 -> 0
B27: SUB TOTAL PAQUETE | D27: =SUM(G11,G18,G25) -> 741.2 | H27: =SUM(L11,L18,L25) -> 0 | M27: =SUM(P11,P18,P25) -> 0
B28: TOTAL PAQUETE | P28: =D27+H27+M27 -> 741.2
B30: Base de costeo: horas del cronograma, responsables R/R-A de la Matriz RACI y tarifas referenciales indicadas en la hoja Supuestos.

Sheet 2.4 Diseño de Datos
B2: PAQUETE DE TRABAJO / ENTREGABLE | D2: 2.4 Diseño de Datos
B3: ACTIVIDAD | D3: COSTOS
B4: CÓDIGO | C4: DESCRIPCIÓN | D4: RECURSOS HUMANOS | H4: MAQUINARIA / EQUIPOS / INFRAESTRUCTURA | M4: CONSUMIBLES / SERVICIOS
D5: Nombre del Recurso | E5: Número de Horas | F5: Costo x Hora (S/) | G5: Costo Total | H5: Nombre del Recurso | I5: Cantidad | J5: Costo x día (S/) | K5: Nro. de días | L5: Total | M5: Nombre del Recurso | N5: Cantidad | O5: Costo Unitario (S/) | P5: IMPORTE
B6: 2.4.1 | C6: Modelo de Información | D6: Piero Ramírez Alva | E6: 24 | F6: =Supuestos!$E$7 -> 23.95 | G6: =E6*F6 -> 574.8
D7: José Manuel Sebastián Mercado Rojas | E7: 4 | F7: =Supuestos!$E$4 -> 28.025 | G7: =E7*F7 -> 112.1
C11: SUB TOTAL ACTIVIDAD | G11: =SUM(G6:G10) -> 686.9 | L11: =SUM(L6:L10) -> 0 | P11: =SUM(P6:P10) -> 0
C12: TOTAL ACTIVIDAD | P12: =G11+L11+P11 -> 686.9
C18: SUB TOTAL ACTIVIDAD | G18: =SUM(G13:G17) -> 0 | L18: =SUM(L13:L17) -> 0 | P18: =SUM(P13:P17) -> 0
C19: TOTAL ACTIVIDAD | P19: =G18+L18+P18 -> 0
C25: SUB TOTAL ACTIVIDAD | G25: =SUM(G20:G24) -> 0 | L25: =SUM(L20:L24) -> 0 | P25: =SUM(P20:P24) -> 0
C26: TOTAL ACTIVIDAD | P26: =G25+L25+P25 -> 0
B27: SUB TOTAL PAQUETE | D27: =SUM(G11,G18,G25) -> 686.9 | H27: =SUM(L11,L18,L25) -> 0 | M27: =SUM(P11,P18,P25) -> 0
B28: TOTAL PAQUETE | P28: =D27+H27+M27 -> 686.9
B30: Base de costeo: horas del cronograma, responsables R/R-A de la Matriz RACI y tarifas referenciales indicadas en la hoja Supuestos.

Sheet 2.5 Diseño UI-UX
B2: PAQUETE DE TRABAJO / ENTREGABLE | D2: 2.5 Diseño UI/UX
B3: ACTIVIDAD | D3: COSTOS
B4: CÓDIGO | C4: DESCRIPCIÓN | D4: RECURSOS HUMANOS | H4: MAQUINARIA / EQUIPOS / INFRAESTRUCTURA | M4: CONSUMIBLES / SERVICIOS
D5: Nombre del Recurso | E5: Número de Horas | F5: Costo x Hora (S/) | G5: Costo Total | H5: Nombre del Recurso | I5: Cantidad | J5: Costo x día (S/) | K5: Nro. de días | L5: Total | M5: Nombre del Recurso | N5: Cantidad | O5: Costo Unitario (S/) | P5: IMPORTE
B6: 2.5.1 | C6: Prototipo del Sistema | D6: Brenda Gabriela Ormeño Bocanegra | E6: 18 | F6: =Supuestos!$E$6 -> 21.875 | G6: =E6*F6 -> 393.75 | M6: Herramienta de prototipado UI/UX | N6: 1 | O6: 200 | P6: =N6*O6 -> 200
D7: José Manuel Sebastián Mercado Rojas | E7: 2 | F7: =Supuestos!$E$4 -> 28.025 | G7: =E7*F7 -> 56.05
C11: SUB TOTAL ACTIVIDAD | G11: =SUM(G6:G10) -> 449.8 | L11: =SUM(L6:L10) -> 0 | P11: =SUM(P6:P10) -> 200
C12: TOTAL ACTIVIDAD | P12: =G11+L11+P11 -> 649.8
C18: SUB TOTAL ACTIVIDAD | G18: =SUM(G13:G17) -> 0 | L18: =SUM(L13:L17) -> 0 | P18: =SUM(P13:P17) -> 0
C19: TOTAL ACTIVIDAD | P19: =G18+L18+P18 -> 0
C25: SUB TOTAL ACTIVIDAD | G25: =SUM(G20:G24) -> 0 | L25: =SUM(L20:L24) -> 0 | P25: =SUM(P20:P24) -> 0
C26: TOTAL ACTIVIDAD | P26: =G25+L25+P25 -> 0
B27: SUB TOTAL PAQUETE | D27: =SUM(G11,G18,G25) -> 449.8 | H27: =SUM(L11,L18,L25) -> 0 | M27: =SUM(P11,P18,P25) -> 200
B28: TOTAL PAQUETE | P28: =D27+H27+M27 -> 649.8
B30: Base de costeo: horas del cronograma, responsables R/R-A de la Matriz RACI y tarifas referenciales indicadas en la hoja Supuestos.

Sheet 3.1 Control de Acceso a Torcly
B2: PAQUETE DE TRABAJO / ENTREGABLE | D2: 3.1 Control de Acceso a Torcly
B3: ACTIVIDAD | D3: COSTOS
B4: CÓDIGO | C4: DESCRIPCIÓN | D4: RECURSOS HUMANOS | H4: MAQUINARIA / EQUIPOS / INFRAESTRUCTURA | M4: CONSUMIBLES / SERVICIOS
D5: Nombre del Recurso | E5: Número de Horas | F5: Costo x Hora (S/) | G5: Costo Total | H5: Nombre del Recurso | I5: Cantidad | J5: Costo x día (S/) | K5: Nro. de días | L5: Total | M5: Nombre del Recurso | N5: Cantidad | O5: Costo Unitario (S/) | P5: IMPORTE
B6: 3.1.1 | C6: Frontend de Seguridad | D6: Brenda Gabriela Ormeño Bocanegra | E6: 10 | F6: =Supuestos!$E$6 -> 21.875 | G6: =E6*F6 -> 218.75
D7: José Manuel Sebastián Mercado Rojas | E7: 2 | F7: =Supuestos!$E$4 -> 28.025 | G7: =E7*F7 -> 56.05
C11: SUB TOTAL ACTIVIDAD | G11: =SUM(G6:G10) -> 274.8 | L11: =SUM(L6:L10) -> 0 | P11: =SUM(P6:P10) -> 0
C12: TOTAL ACTIVIDAD | P12: =G11+L11+P11 -> 274.8
B13: 3.1.2 | C13: Backend de Seguridad | D13: Carmen Katerin Vega Meza | E13: 22 | F13: =Supuestos!$E$8 -> 21.875 | G13: =E13*F13 -> 481.25
D14: José Manuel Sebastián Mercado Rojas | E14: 6 | F14: =Supuestos!$E$4 -> 28.025 | G14: =E14*F14 -> 168.15
C18: SUB TOTAL ACTIVIDAD | G18: =SUM(G13:G17) -> 649.4 | L18: =SUM(L13:L17) -> 0 | P18: =SUM(P13:P17) -> 0
C19: TOTAL ACTIVIDAD | P19: =G18+L18+P18 -> 649.4
B20: 3.1.3 | C20: Administración de Usuarios | D20: Brenda Gabriela Ormeño Bocanegra | E20: 12 | F20: =Supuestos!$E$6 -> 21.875 | G20: =E20*F20 -> 262.5
C25: SUB TOTAL ACTIVIDAD | G25: =SUM(G20:G24) -> 262.5 | L25: =SUM(L20:L24) -> 0 | P25: =SUM(P20:P24) -> 0
C26: TOTAL ACTIVIDAD | P26: =G25+L25+P25 -> 262.5
B27: SUB TOTAL PAQUETE | D27: =SUM(G11,G18,G25) -> 1186.7 | H27: =SUM(L11,L18,L25) -> 0 | M27: =SUM(P11,P18,P25) -> 0
B28: TOTAL PAQUETE | P28: =D27+H27+M27 -> 1186.7
B30: Base de costeo: horas del cronograma, responsables R/R-A de la Matriz RACI y tarifas referenciales indicadas en la hoja Supuestos.

Sheet 4.1 Gestión de Clientes
B2: PAQUETE DE TRABAJO / ENTREGABLE | D2: 4.1 Gestión de Clientes
B3: ACTIVIDAD | D3: COSTOS
B4: CÓDIGO | C4: DESCRIPCIÓN | D4: RECURSOS HUMANOS | H4: MAQUINARIA / EQUIPOS / INFRAESTRUCTURA | M4: CONSUMIBLES / SERVICIOS
D5: Nombre del Recurso | E5: Número de Horas | F5: Costo x Hora (S/) | G5: Costo Total | H5: Nombre del Recurso | I5: Cantidad | J5: Costo x día (S/) | K5: Nro. de días | L5: Total | M5: Nombre del Recurso | N5: Cantidad | O5: Costo Unitario (S/) | P5: IMPORTE
B6: 4.1.1 | C6: Frontend de Clientes | D6: Brenda Gabriela Ormeño Bocanegra | E6: 11 | F6: =Supuestos!$E$6 -> 21.875 | G6: =E6*F6 -> 240.625
D7: José Manuel Sebastián Mercado Rojas | E7: 1 | F7: =Supuestos!$E$4 -> 28.025 | G7: =E7*F7 -> 28.025
C11: SUB TOTAL ACTIVIDAD | G11: =SUM(G6:G10) -> 268.65 | L11: =SUM(L6:L10) -> 0 | P11: =SUM(P6:P10) -> 0
C12: TOTAL ACTIVIDAD | P12: =G11+L11+P11 -> 268.65
B13: 4.1.2 | C13: Backend de Clientes | D13: Carmen Katerin Vega Meza | E13: 6 | F13: =Supuestos!$E$8 -> 21.875 | G13: =E13*F13 -> 131.25
D14: Arian Armando Bautista Quezada | E14: 4 | F14: =Supuestos!$E$5 -> 24.8 | G14: =E14*F14 -> 99.2
D15: José Manuel Sebastián Mercado Rojas | E15: 2 | F15: =Supuestos!$E$4 -> 28.025 | G15: =E15*F15 -> 56.05
C18: SUB TOTAL ACTIVIDAD | G18: =SUM(G13:G17) -> 286.5 | L18: =SUM(L13:L17) -> 0 | P18: =SUM(P13:P17) -> 0
C19: TOTAL ACTIVIDAD | P19: =G18+L18+P18 -> 286.5
C25: SUB TOTAL ACTIVIDAD | G25: =SUM(G20:G24) -> 0 | L25: =SUM(L20:L24) -> 0 | P25: =SUM(P20:P24) -> 0
C26: TOTAL ACTIVIDAD | P26: =G25+L25+P25 -> 0
B27: SUB TOTAL PAQUETE | D27: =SUM(G11,G18,G25) -> 555.15 | H27: =SUM(L11,L18,L25) -> 0 | M27: =SUM(P11,P18,P25) -> 0
B28: TOTAL PAQUETE | P28: =D27+H27+M27 -> 555.15
B30: Base de costeo: horas del cronograma, responsables R/R-A de la Matriz RACI y tarifas referenciales indicadas en la hoja Supuestos.

Sheet 4.2 Gestión de Vehículos
B2: PAQUETE DE TRABAJO / ENTREGABLE | D2: 4.2 Gestión de Vehículos
B3: ACTIVIDAD | D3: COSTOS
B4: CÓDIGO | C4: DESCRIPCIÓN | D4: RECURSOS HUMANOS | H4: MAQUINARIA / EQUIPOS / INFRAESTRUCTURA | M4: CONSUMIBLES / SERVICIOS
D5: Nombre del Recurso | E5: Número de Horas | F5: Costo x Hora (S/) | G5: Costo Total | H5: Nombre del Recurso | I5: Cantidad | J5: Costo x día (S/) | K5: Nro. de días | L5: Total | M5: Nombre del Recurso | N5: Cantidad | O5: Costo Unitario (S/) | P5: IMPORTE
B6: 4.2.1 | C6: Frontend de Vehículos | D6: Brenda Gabriela Ormeño Bocanegra | E6: 11 | F6: =Supuestos!$E$6 -> 21.875 | G6: =E6*F6 -> 240.625
D7: José Manuel Sebastián Mercado Rojas | E7: 1 | F7: =Supuestos!$E$4 -> 28.025 | G7: =E7*F7 -> 28.025
C11: SUB TOTAL ACTIVIDAD | G11: =SUM(G6:G10) -> 268.65 | L11: =SUM(L6:L10) -> 0 | P11: =SUM(P6:P10) -> 0
C12: TOTAL ACTIVIDAD | P12: =G11+L11+P11 -> 268.65
B13: 4.2.2 | C13: Backend de Vehículos | D13: Carmen Katerin Vega Meza | E13: 10 | F13: =Supuestos!$E$8 -> 21.875 | G13: =E13*F13 -> 218.75
D14: José Manuel Sebastián Mercado Rojas | E14: 2 | F14: =Supuestos!$E$4 -> 28.025 | G14: =E14*F14 -> 56.05
C18: SUB TOTAL ACTIVIDAD | G18: =SUM(G13:G17) -> 274.8 | L18: =SUM(L13:L17) -> 0 | P18: =SUM(P13:P17) -> 0
C19: TOTAL ACTIVIDAD | P19: =G18+L18+P18 -> 274.8
C25: SUB TOTAL ACTIVIDAD | G25: =SUM(G20:G24) -> 0 | L25: =SUM(L20:L24) -> 0 | P25: =SUM(P20:P24) -> 0
C26: TOTAL ACTIVIDAD | P26: =G25+L25+P25 -> 0
B27: SUB TOTAL PAQUETE | D27: =SUM(G11,G18,G25) -> 543.45 | H27: =SUM(L11,L18,L25) -> 0 | M27: =SUM(P11,P18,P25) -> 0
B28: TOTAL PAQUETE | P28: =D27+H27+M27 -> 543.45
B30: Base de costeo: horas del cronograma, responsables R/R-A de la Matriz RACI y tarifas referenciales indicadas en la hoja Supuestos.

Sheet 5.1 Catálogo de Productos
B2: PAQUETE DE TRABAJO / ENTREGABLE | D2: 5.1 Catálogo de Productos
B3: ACTIVIDAD | D3: COSTOS
B4: CÓDIGO | C4: DESCRIPCIÓN | D4: RECURSOS HUMANOS | H4: MAQUINARIA / EQUIPOS / INFRAESTRUCTURA | M4: CONSUMIBLES / SERVICIOS
D5: Nombre del Recurso | E5: Número de Horas | F5: Costo x Hora (S/) | G5: Costo Total | H5: Nombre del Recurso | I5: Cantidad | J5: Costo x día (S/) | K5: Nro. de días | L5: Total | M5: Nombre del Recurso | N5: Cantidad | O5: Costo Unitario (S/) | P5: IMPORTE
B6: 5.1.1 | C6: Frontend de Productos | D6: Piero Ramírez Alva | E6: 10 | F6: =Supuestos!$E$7 -> 23.95 | G6: =E6*F6 -> 239.5
D7: José Manuel Sebastián Mercado Rojas | E7: 2 | F7: =Supuestos!$E$4 -> 28.025 | G7: =E7*F7 -> 56.05
C11: SUB TOTAL ACTIVIDAD | G11: =SUM(G6:G10) -> 295.55 | L11: =SUM(L6:L10) -> 0 | P11: =SUM(P6:P10) -> 0
C12: TOTAL ACTIVIDAD | P12: =G11+L11+P11 -> 295.55
B13: 5.1.2 | C13: Backend de Productos | D13: Piero Ramírez Alva | E13: 10 | F13: =Supuestos!$E$7 -> 23.95 | G13: =E13*F13 -> 239.5
D14: José Manuel Sebastián Mercado Rojas | E14: 2 | F14: =Supuestos!$E$4 -> 28.025 | G14: =E14*F14 -> 56.05
C18: SUB TOTAL ACTIVIDAD | G18: =SUM(G13:G17) -> 295.55 | L18: =SUM(L13:L17) -> 0 | P18: =SUM(P13:P17) -> 0
C19: TOTAL ACTIVIDAD | P19: =G18+L18+P18 -> 295.55
C25: SUB TOTAL ACTIVIDAD | G25: =SUM(G20:G24) -> 0 | L25: =SUM(L20:L24) -> 0 | P25: =SUM(P20:P24) -> 0
C26: TOTAL ACTIVIDAD | P26: =G25+L25+P25 -> 0
B27: SUB TOTAL PAQUETE | D27: =SUM(G11,G18,G25) -> 591.1 | H27: =SUM(L11,L18,L25) -> 0 | M27: =SUM(P11,P18,P25) -> 0
B28: TOTAL PAQUETE | P28: =D27+H27+M27 -> 591.1
B30: Base de costeo: horas del cronograma, responsables R/R-A de la Matriz RACI y tarifas referenciales indicadas en la hoja Supuestos.

Sheet 5.2 Control de Inventario
B2: PAQUETE DE TRABAJO / ENTREGABLE | D2: 5.2 Control de Inventario
B3: ACTIVIDAD | D3: COSTOS
B4: CÓDIGO | C4: DESCRIPCIÓN | D4: RECURSOS HUMANOS | H4: MAQUINARIA / EQUIPOS / INFRAESTRUCTURA | M4: CONSUMIBLES / SERVICIOS
D5: Nombre del Recurso | E5: Número de Horas | F5: Costo x Hora (S/) | G5: Costo Total | H5: Nombre del Recurso | I5: Cantidad | J5: Costo x día (S/) | K5: Nro. de días | L5: Total | M5: Nombre del Recurso | N5: Cantidad | O5: Costo Unitario (S/) | P5: IMPORTE
B6: 5.2.1 | C6: Frontend de Inventario | D6: Piero Ramírez Alva | E6: 12 | F6: =Supuestos!$E$7 -> 23.95 | G6: =E6*F6 -> 287.4 | H6: Lector de código de barras | I6: 1 | J6: 1000 | K6: 1 | L6: =I6*J6*K6 -> 1000
D7: José Manuel Sebastián Mercado Rojas | E7: 4 | F7: =Supuestos!$E$4 -> 28.025 | G7: =E7*F7 -> 112.1
C11: SUB TOTAL ACTIVIDAD | G11: =SUM(G6:G10) -> 399.5 | L11: =SUM(L6:L10) -> 1000 | P11: =SUM(P6:P10) -> 0
C12: TOTAL ACTIVIDAD | P12: =G11+L11+P11 -> 1399.5
B13: 5.2.2 | C13: Backend de Inventario | D13: Piero Ramírez Alva | E13: 20 | F13: =Supuestos!$E$7 -> 23.95 | G13: =E13*F13 -> 479
D14: José Manuel Sebastián Mercado Rojas | E14: 4 | F14: =Supuestos!$E$4 -> 28.025 | G14: =E14*F14 -> 112.1
C18: SUB TOTAL ACTIVIDAD | G18: =SUM(G13:G17) -> 591.1 | L18: =SUM(L13:L17) -> 0 | P18: =SUM(P13:P17) -> 0
C19: TOTAL ACTIVIDAD | P19: =G18+L18+P18 -> 591.1
C25: SUB TOTAL ACTIVIDAD | G25: =SUM(G20:G24) -> 0 | L25: =SUM(L20:L24) -> 0 | P25: =SUM(P20:P24) -> 0
C26: TOTAL ACTIVIDAD | P26: =G25+L25+P25 -> 0
B27: SUB TOTAL PAQUETE | D27: =SUM(G11,G18,G25) -> 990.6 | H27: =SUM(L11,L18,L25) -> 1000 | M27: =SUM(P11,P18,P25) -> 0
B28: TOTAL PAQUETE | P28: =D27+H27+M27 -> 1990.6
B30: Base de costeo: horas del cronograma, responsables R/R-A de la Matriz RACI y tarifas referenciales indicadas en la hoja Supuestos.

Sheet 6.1 Catálogo de Servicios
B2: PAQUETE DE TRABAJO / ENTREGABLE | D2: 6.1 Catálogo de Servicios
B3: ACTIVIDAD | D3: COSTOS
B4: CÓDIGO | C4: DESCRIPCIÓN | D4: RECURSOS HUMANOS | H4: MAQUINARIA / EQUIPOS / INFRAESTRUCTURA | M4: CONSUMIBLES / SERVICIOS
D5: Nombre del Recurso | E5: Número de Horas | F5: Costo x Hora (S/) | G5: Costo Total | H5: Nombre del Recurso | I5: Cantidad | J5: Costo x día (S/) | K5: Nro. de días | L5: Total | M5: Nombre del Recurso | N5: Cantidad | O5: Costo Unitario (S/) | P5: IMPORTE
B6: 6.1.1 | C6: Frontend de Servicios | D6: Brenda Gabriela Ormeño Bocanegra | E6: 12 | F6: =Supuestos!$E$6 -> 21.875 | G6: =E6*F6 -> 262.5
C11: SUB TOTAL ACTIVIDAD | G11: =SUM(G6:G10) -> 262.5 | L11: =SUM(L6:L10) -> 0 | P11: =SUM(P6:P10) -> 0
C12: TOTAL ACTIVIDAD | P12: =G11+L11+P11 -> 262.5
B13: 6.1.2 | C13: Backend de Servicios | D13: Carmen Katerin Vega Meza | E13: 10 | F13: =Supuestos!$E$8 -> 21.875 | G13: =E13*F13 -> 218.75
D14: José Manuel Sebastián Mercado Rojas | E14: 2 | F14: =Supuestos!$E$4 -> 28.025 | G14: =E14*F14 -> 56.05
C18: SUB TOTAL ACTIVIDAD | G18: =SUM(G13:G17) -> 274.8 | L18: =SUM(L13:L17) -> 0 | P18: =SUM(P13:P17) -> 0
C19: TOTAL ACTIVIDAD | P19: =G18+L18+P18 -> 274.8
C25: SUB TOTAL ACTIVIDAD | G25: =SUM(G20:G24) -> 0 | L25: =SUM(L20:L24) -> 0 | P25: =SUM(P20:P24) -> 0
C26: TOTAL ACTIVIDAD | P26: =G25+L25+P25 -> 0
B27: SUB TOTAL PAQUETE | D27: =SUM(G11,G18,G25) -> 537.3 | H27: =SUM(L11,L18,L25) -> 0 | M27: =SUM(P11,P18,P25) -> 0
B28: TOTAL PAQUETE | P28: =D27+H27+M27 -> 537.3
B30: Base de costeo: horas del cronograma, responsables R/R-A de la Matriz RACI y tarifas referenciales indicadas en la hoja Supuestos.

Sheet 7.1 Agenda del Taller
B2: PAQUETE DE TRABAJO / ENTREGABLE | D2: 7.1 Agenda del Taller
B3: ACTIVIDAD | D3: COSTOS
B4: CÓDIGO | C4: DESCRIPCIÓN | D4: RECURSOS HUMANOS | H4: MAQUINARIA / EQUIPOS / INFRAESTRUCTURA | M4: CONSUMIBLES / SERVICIOS
D5: Nombre del Recurso | E5: Número de Horas | F5: Costo x Hora (S/) | G5: Costo Total | H5: Nombre del Recurso | I5: Cantidad | J5: Costo x día (S/) | K5: Nro. de días | L5: Total | M5: Nombre del Recurso | N5: Cantidad | O5: Costo Unitario (S/) | P5: IMPORTE
B6: 7.1.1 | C6: Frontend de Citas | D6: Brenda Gabriela Ormeño Bocanegra | E6: 15 | F6: =Supuestos!$E$6 -> 21.875 | G6: =E6*F6 -> 328.125
D7: José Manuel Sebastián Mercado Rojas | E7: 1 | F7: =Supuestos!$E$4 -> 28.025 | G7: =E7*F7 -> 28.025
C11: SUB TOTAL ACTIVIDAD | G11: =SUM(G6:G10) -> 356.15 | L11: =SUM(L6:L10) -> 0 | P11: =SUM(P6:P10) -> 0
C12: TOTAL ACTIVIDAD | P12: =G11+L11+P11 -> 356.15
B13: 7.1.2 | C13: Backend de Citas | D13: Arian Armando Bautista Quezada | E13: 18 | F13: =Supuestos!$E$5 -> 24.8 | G13: =E13*F13 -> 446.4
D14: José Manuel Sebastián Mercado Rojas | E14: 2 | F14: =Supuestos!$E$4 -> 28.025 | G14: =E14*F14 -> 56.05
C18: SUB TOTAL ACTIVIDAD | G18: =SUM(G13:G17) -> 502.45 | L18: =SUM(L13:L17) -> 0 | P18: =SUM(P13:P17) -> 0
C19: TOTAL ACTIVIDAD | P19: =G18+L18+P18 -> 502.45
C25: SUB TOTAL ACTIVIDAD | G25: =SUM(G20:G24) -> 0 | L25: =SUM(L20:L24) -> 0 | P25: =SUM(P20:P24) -> 0
C26: TOTAL ACTIVIDAD | P26: =G25+L25+P25 -> 0
B27: SUB TOTAL PAQUETE | D27: =SUM(G11,G18,G25) -> 858.6 | H27: =SUM(L11,L18,L25) -> 0 | M27: =SUM(P11,P18,P25) -> 0
B28: TOTAL PAQUETE | P28: =D27+H27+M27 -> 858.6
B30: Base de costeo: horas del cronograma, responsables R/R-A de la Matriz RACI y tarifas referenciales indicadas en la hoja Supuestos.

Sheet 8.1 Orden de Trabajo
B2: PAQUETE DE TRABAJO / ENTREGABLE | D2: 8.1 Orden de Trabajo
B3: ACTIVIDAD | D3: COSTOS
B4: CÓDIGO | C4: DESCRIPCIÓN | D4: RECURSOS HUMANOS | H4: MAQUINARIA / EQUIPOS / INFRAESTRUCTURA | M4: CONSUMIBLES / SERVICIOS
D5: Nombre del Recurso | E5: Número de Horas | F5: Costo x Hora (S/) | G5: Costo Total | H5: Nombre del Recurso | I5: Cantidad | J5: Costo x día (S/) | K5: Nro. de días | L5: Total | M5: Nombre del Recurso | N5: Cantidad | O5: Costo Unitario (S/) | P5: IMPORTE
B6: 8.1.1 | C6: Registro de Atención | D6: Arian Armando Bautista Quezada | E6: 20 | F6: =Supuestos!$E$5 -> 24.8 | G6: =E6*F6 -> 496
D7: José Manuel Sebastián Mercado Rojas | E7: 4 | F7: =Supuestos!$E$4 -> 28.025 | G7: =E7*F7 -> 112.1
C11: SUB TOTAL ACTIVIDAD | G11: =SUM(G6:G10) -> 608.1 | L11: =SUM(L6:L10) -> 0 | P11: =SUM(P6:P10) -> 0
C12: TOTAL ACTIVIDAD | P12: =G11+L11+P11 -> 608.1
B13: 8.1.2 | C13: Ejecución del Servicio | D13: Carmen Katerin Vega Meza | E13: 16 | F13: =Supuestos!$E$8 -> 21.875 | G13: =E13*F13 -> 350
D14: José Manuel Sebastián Mercado Rojas | E14: 4 | F14: =Supuestos!$E$4 -> 28.025 | G14: =E14*F14 -> 112.1
C18: SUB TOTAL ACTIVIDAD | G18: =SUM(G13:G17) -> 462.1 | L18: =SUM(L13:L17) -> 0 | P18: =SUM(P13:P17) -> 0
C19: TOTAL ACTIVIDAD | P19: =G18+L18+P18 -> 462.1
B20: 8.1.3 | C20: Finalización de Atención | D20: Brenda Gabriela Ormeño Bocanegra | E20: 8 | F20: =Supuestos!$E$6 -> 21.875 | G20: =E20*F20 -> 175
D21: Arian Armando Bautista Quezada | E21: 4 | F21: =Supuestos!$E$5 -> 24.8 | G21: =E21*F21 -> 99.2
C25: SUB TOTAL ACTIVIDAD | G25: =SUM(G20:G24) -> 274.2 | L25: =SUM(L20:L24) -> 0 | P25: =SUM(P20:P24) -> 0
C26: TOTAL ACTIVIDAD | P26: =G25+L25+P25 -> 274.2
B27: SUB TOTAL PAQUETE | D27: =SUM(G11,G18,G25) -> 1344.4 | H27: =SUM(L11,L18,L25) -> 0 | M27: =SUM(P11,P18,P25) -> 0
B28: TOTAL PAQUETE | P28: =D27+H27+M27 -> 1344.4
B30: Base de costeo: horas del cronograma, responsables R/R-A de la Matriz RACI y tarifas referenciales indicadas en la hoja Supuestos.

Sheet 8.2 Seguimiento del Taller
B2: PAQUETE DE TRABAJO / ENTREGABLE | D2: 8.2 Seguimiento del Taller
B3: ACTIVIDAD | D3: COSTOS
B4: CÓDIGO | C4: DESCRIPCIÓN | D4: RECURSOS HUMANOS | H4: MAQUINARIA / EQUIPOS / INFRAESTRUCTURA | M4: CONSUMIBLES / SERVICIOS
D5: Nombre del Recurso | E5: Número de Horas | F5: Costo x Hora (S/) | G5: Costo Total | H5: Nombre del Recurso | I5: Cantidad | J5: Costo x día (S/) | K5: Nro. de días | L5: Total | M5: Nombre del Recurso | N5: Cantidad | O5: Costo Unitario (S/) | P5: IMPORTE
B6: 8.2.1 | C6: Control de Estados | D6: Carmen Katerin Vega Meza | E6: 13 | F6: =Supuestos!$E$8 -> 21.875 | G6: =E6*F6 -> 284.375
D7: José Manuel Sebastián Mercado Rojas | E7: 3 | F7: =Supuestos!$E$4 -> 28.025 | G7: =E7*F7 -> 84.075
C11: SUB TOTAL ACTIVIDAD | G11: =SUM(G6:G10) -> 368.45 | L11: =SUM(L6:L10) -> 0 | P11: =SUM(P6:P10) -> 0
C12: TOTAL ACTIVIDAD | P12: =G11+L11+P11 -> 368.45
C18: SUB TOTAL ACTIVIDAD | G18: =SUM(G13:G17) -> 0 | L18: =SUM(L13:L17) -> 0 | P18: =SUM(P13:P17) -> 0
C19: TOTAL ACTIVIDAD | P19: =G18+L18+P18 -> 0
C25: SUB TOTAL ACTIVIDAD | G25: =SUM(G20:G24) -> 0 | L25: =SUM(L20:L24) -> 0 | P25: =SUM(P20:P24) -> 0
C26: TOTAL ACTIVIDAD | P26: =G25+L25+P25 -> 0
B27: SUB TOTAL PAQUETE | D27: =SUM(G11,G18,G25) -> 368.45 | H27: =SUM(L11,L18,L25) -> 0 | M27: =SUM(P11,P18,P25) -> 0
B28: TOTAL PAQUETE | P28: =D27+H27+M27 -> 368.45
B30: Base de costeo: horas del cronograma, responsables R/R-A de la Matriz RACI y tarifas referenciales indicadas en la hoja Supuestos.

Sheet 9.1 Gestión de Ventas
B2: PAQUETE DE TRABAJO / ENTREGABLE | D2: 9.1 Gestión de Ventas
B3: ACTIVIDAD | D3: COSTOS
B4: CÓDIGO | C4: DESCRIPCIÓN | D4: RECURSOS HUMANOS | H4: MAQUINARIA / EQUIPOS / INFRAESTRUCTURA | M4: CONSUMIBLES / SERVICIOS
D5: Nombre del Recurso | E5: Número de Horas | F5: Costo x Hora (S/) | G5: Costo Total | H5: Nombre del Recurso | I5: Cantidad | J5: Costo x día (S/) | K5: Nro. de días | L5: Total | M5: Nombre del Recurso | N5: Cantidad | O5: Costo Unitario (S/) | P5: IMPORTE
B6: 9.1.1 | C6: Registro Comercial | D6: Brenda Gabriela Ormeño Bocanegra | E6: 15 | F6: =Supuestos!$E$6 -> 21.875 | G6: =E6*F6 -> 328.125
D7: José Manuel Sebastián Mercado Rojas | E7: 1 | F7: =Supuestos!$E$4 -> 28.025 | G7: =E7*F7 -> 28.025
C11: SUB TOTAL ACTIVIDAD | G11: =SUM(G6:G10) -> 356.15 | L11: =SUM(L6:L10) -> 0 | P11: =SUM(P6:P10) -> 0
C12: TOTAL ACTIVIDAD | P12: =G11+L11+P11 -> 356.15
C18: SUB TOTAL ACTIVIDAD | G18: =SUM(G13:G17) -> 0 | L18: =SUM(L13:L17) -> 0 | P18: =SUM(P13:P17) -> 0
C19: TOTAL ACTIVIDAD | P19: =G18+L18+P18 -> 0
C25: SUB TOTAL ACTIVIDAD | G25: =SUM(G20:G24) -> 0 | L25: =SUM(L20:L24) -> 0 | P25: =SUM(P20:P24) -> 0
C26: TOTAL ACTIVIDAD | P26: =G25+L25+P25 -> 0
B27: SUB TOTAL PAQUETE | D27: =SUM(G11,G18,G25) -> 356.15 | H27: =SUM(L11,L18,L25) -> 0 | M27: =SUM(P11,P18,P25) -> 0
B28: TOTAL PAQUETE | P28: =D27+H27+M27 -> 356.15
B30: Base de costeo: horas del cronograma, responsables R/R-A de la Matriz RACI y tarifas referenciales indicadas en la hoja Supuestos.

Sheet 9.2 Gestión de Pagos
B2: PAQUETE DE TRABAJO / ENTREGABLE | D2: 9.2 Gestión de Pagos
B3: ACTIVIDAD | D3: COSTOS
B4: CÓDIGO | C4: DESCRIPCIÓN | D4: RECURSOS HUMANOS | H4: MAQUINARIA / EQUIPOS / INFRAESTRUCTURA | M4: CONSUMIBLES / SERVICIOS
D5: Nombre del Recurso | E5: Número de Horas | F5: Costo x Hora (S/) | G5: Costo Total | H5: Nombre del Recurso | I5: Cantidad | J5: Costo x día (S/) | K5: Nro. de días | L5: Total | M5: Nombre del Recurso | N5: Cantidad | O5: Costo Unitario (S/) | P5: IMPORTE
B6: 9.2.1 | C6: Registro de Pagos | D6: Piero Ramírez Alva | E6: 24 | F6: =Supuestos!$E$7 -> 23.95 | G6: =E6*F6 -> 574.8
D7: José Manuel Sebastián Mercado Rojas | E7: 4 | F7: =Supuestos!$E$4 -> 28.025 | G7: =E7*F7 -> 112.1
C11: SUB TOTAL ACTIVIDAD | G11: =SUM(G6:G10) -> 686.9 | L11: =SUM(L6:L10) -> 0 | P11: =SUM(P6:P10) -> 0
C12: TOTAL ACTIVIDAD | P12: =G11+L11+P11 -> 686.9
C18: SUB TOTAL ACTIVIDAD | G18: =SUM(G13:G17) -> 0 | L18: =SUM(L13:L17) -> 0 | P18: =SUM(P13:P17) -> 0
C19: TOTAL ACTIVIDAD | P19: =G18+L18+P18 -> 0
C25: SUB TOTAL ACTIVIDAD | G25: =SUM(G20:G24) -> 0 | L25: =SUM(L20:L24) -> 0 | P25: =SUM(P20:P24) -> 0
C26: TOTAL ACTIVIDAD | P26: =G25+L25+P25 -> 0
B27: SUB TOTAL PAQUETE | D27: =SUM(G11,G18,G25) -> 686.9 | H27: =SUM(L11,L18,L25) -> 0 | M27: =SUM(P11,P18,P25) -> 0
B28: TOTAL PAQUETE | P28: =D27+H27+M27 -> 686.9
B30: Base de costeo: horas del cronograma, responsables R/R-A de la Matriz RACI y tarifas referenciales indicadas en la hoja Supuestos.

Sheet 10.1 Consulta Centralizada
B2: PAQUETE DE TRABAJO / ENTREGABLE | D2: 10.1 Consulta Centralizada
B3: ACTIVIDAD | D3: COSTOS
B4: CÓDIGO | C4: DESCRIPCIÓN | D4: RECURSOS HUMANOS | H4: MAQUINARIA / EQUIPOS / INFRAESTRUCTURA | M4: CONSUMIBLES / SERVICIOS
D5: Nombre del Recurso | E5: Número de Horas | F5: Costo x Hora (S/) | G5: Costo Total | H5: Nombre del Recurso | I5: Cantidad | J5: Costo x día (S/) | K5: Nro. de días | L5: Total | M5: Nombre del Recurso | N5: Cantidad | O5: Costo Unitario (S/) | P5: IMPORTE
B6: 10.1.1 | C6: Panel Operativo | D6: Arian Armando Bautista Quezada | E6: 18 | F6: =Supuestos!$E$5 -> 24.8 | G6: =E6*F6 -> 446.4
D7: José Manuel Sebastián Mercado Rojas | E7: 2 | F7: =Supuestos!$E$4 -> 28.025 | G7: =E7*F7 -> 56.05
C11: SUB TOTAL ACTIVIDAD | G11: =SUM(G6:G10) -> 502.45 | L11: =SUM(L6:L10) -> 0 | P11: =SUM(P6:P10) -> 0
C12: TOTAL ACTIVIDAD | P12: =G11+L11+P11 -> 502.45
C18: SUB TOTAL ACTIVIDAD | G18: =SUM(G13:G17) -> 0 | L18: =SUM(L13:L17) -> 0 | P18: =SUM(P13:P17) -> 0
C19: TOTAL ACTIVIDAD | P19: =G18+L18+P18 -> 0
C25: SUB TOTAL ACTIVIDAD | G25: =SUM(G20:G24) -> 0 | L25: =SUM(L20:L24) -> 0 | P25: =SUM(P20:P24) -> 0
C26: TOTAL ACTIVIDAD | P26: =G25+L25+P25 -> 0
B27: SUB TOTAL PAQUETE | D27: =SUM(G11,G18,G25) -> 502.45 | H27: =SUM(L11,L18,L25) -> 0 | M27: =SUM(P11,P18,P25) -> 0
B28: TOTAL PAQUETE | P28: =D27+H27+M27 -> 502.45
B30: Base de costeo: horas del cronograma, responsables R/R-A de la Matriz RACI y tarifas referenciales indicadas en la hoja Supuestos.

Sheet 11.1 Panel Analítico de Torcly
B2: PAQUETE DE TRABAJO / ENTREGABLE | D2: 11.1 Panel Analítico de Torcly
B3: ACTIVIDAD | D3: COSTOS
B4: CÓDIGO | C4: DESCRIPCIÓN | D4: RECURSOS HUMANOS | H4: MAQUINARIA / EQUIPOS / INFRAESTRUCTURA | M4: CONSUMIBLES / SERVICIOS
D5: Nombre del Recurso | E5: Número de Horas | F5: Costo x Hora (S/) | G5: Costo Total | H5: Nombre del Recurso | I5: Cantidad | J5: Costo x día (S/) | K5: Nro. de días | L5: Total | M5: Nombre del Recurso | N5: Cantidad | O5: Costo Unitario (S/) | P5: IMPORTE
B6: 11.1.1 | C6: Preparación Analítica | D6: Piero Ramírez Alva | E6: 3 | F6: =Supuestos!$E$7 -> 23.95 | G6: =E6*F6 -> 71.85
D7: Arian Armando Bautista Quezada | E7: 8 | F7: =Supuestos!$E$5 -> 24.8 | G7: =E7*F7 -> 198.4
D8: José Manuel Sebastián Mercado Rojas | E8: 1 | F8: =Supuestos!$E$4 -> 28.025 | G8: =E8*F8 -> 28.025
C11: SUB TOTAL ACTIVIDAD | G11: =SUM(G6:G10) -> 298.275 | L11: =SUM(L6:L10) -> 0 | P11: =SUM(P6:P10) -> 0
C12: TOTAL ACTIVIDAD | P12: =G11+L11+P11 -> 298.275
B13: 11.1.2 | C13: Dashboard BI | D13: Arian Armando Bautista Quezada | E13: 16 | F13: =Supuestos!$E$5 -> 24.8 | G13: =E13*F13 -> 396.8 | M13: Herramienta / servicio BI | N13: 1 | O13: 200 | P13: =N13*O13 -> 200
D14: Brenda Gabriela Ormeño Bocanegra | E14: 8 | F14: =Supuestos!$E$6 -> 21.875 | G14: =E14*F14 -> 175
C18: SUB TOTAL ACTIVIDAD | G18: =SUM(G13:G17) -> 571.8 | L18: =SUM(L13:L17) -> 0 | P18: =SUM(P13:P17) -> 200
C19: TOTAL ACTIVIDAD | P19: =G18+L18+P18 -> 771.8
C25: SUB TOTAL ACTIVIDAD | G25: =SUM(G20:G24) -> 0 | L25: =SUM(L20:L24) -> 0 | P25: =SUM(P20:P24) -> 0
C26: TOTAL ACTIVIDAD | P26: =G25+L25+P25 -> 0
B27: SUB TOTAL PAQUETE | D27: =SUM(G11,G18,G25) -> 870.075 | H27: =SUM(L11,L18,L25) -> 0 | M27: =SUM(P11,P18,P25) -> 200
B28: TOTAL PAQUETE | P28: =D27+H27+M27 -> 1070.075
B30: Base de costeo: horas del cronograma, responsables R/R-A de la Matriz RACI y tarifas referenciales indicadas en la hoja Supuestos.

Sheet 12.1 Motor de Apoyo a Reposició
B2: PAQUETE DE TRABAJO / ENTREGABLE | D2: 12.1 Motor de Apoyo a Reposición
B3: ACTIVIDAD | D3: COSTOS
B4: CÓDIGO | C4: DESCRIPCIÓN | D4: RECURSOS HUMANOS | H4: MAQUINARIA / EQUIPOS / INFRAESTRUCTURA | M4: CONSUMIBLES / SERVICIOS
